<?xml version="1.0" encoding="utf-8" ?>
<robot xmlns:xacro="http://ros.org/wiki/xacro" name="ur5" >
    <link name="base_link">
        <visual>
            <geometry>
                <mesh filename="package://ur_description/meshes/ur5/visual/base.dae" />
            </geometry>
            <material name="LightGrey">
                <color rgba="0.7 0.7 0.7 1.0" />
            </material>
        </visual>
        <collision>
            <geometry>
                <mesh filename="package://ur_description/meshes/ur5/collision/base.stl" />
            </geometry>
        </collision>
        <inertial>
            <mass value="4.0" />
            <origin rpy="0 0 0" xyz="0.0 0.0 1.0" />
            <inertia ixx="0.00443333156" ixy="0.0" ixz="0.0" iyy="0.00443333156" iyz="0.0" izz="0.0072" />
        </inertial>
    </link>
    <joint name="shoulder_pan_joint" type="revolute">
        <parent link="base_link" />
        <child link="shoulder_link" />
        <origin rpy="0.0 0.0 0.0" xyz="0.0 0.0 0.089159" />
        <axis xyz="0 0 1" />
        <limit effort="150.0" lower="-3.14159265" upper="3.14159265" velocity="3.15" />
        <dynamics damping="0.0" friction="0.0" />
    </joint>
    <link name="shoulder_link">
        <visual>
            <geometry>
                <mesh filename="package://ur_description/meshes/ur5/visual/shoulder.dae" />
            </geometry>
            <material name="LightGrey">
                <color rgba="0.7 0.7 0.7 1.0" />
            </material>
        </visual>
        <collision>
            <geometry>
                <mesh filename="package://ur_description/meshes/ur5/collision/shoulder.stl" />
            </geometry>
        </collision>
        <inertial>
            <mass value="3.7" />
            <origin rpy="0 0 0" xyz="0.0 0.0 0.0" />
            <inertia ixx="0.010267495893" ixy="0.0" ixz="0.0" iyy="0.010267495893" iyz="0.0" izz="0.00666" />
        </inertial>
    </link>
    <joint name="shoulder_lift_joint" type="revolute">
        <parent link="shoulder_link" />
        <child link="upper_arm_link" />
        <origin rpy="0.0 1.570796325 0.0" xyz="0.0 0.13585 0.0" />
        <axis xyz="0 1 0" />
        <limit effort="150.0" lower="-3.14159265" upper="3.14159265" velocity="3.15" />
        <dynamics damping="0.0" friction="0.0" />
    </joint>
    <link name="upper_arm_link">
        <visual>
            <geometry>
                <mesh filename="package://ur_description/meshes/ur5/visual/upperarm.dae" />
            </geometry>
            <material name="LightGrey">
                <color rgba="0.7 0.7 0.7 1.0" />
            </material>
        </visual>
        <collision>
            <geometry>
                <mesh filename="package://ur_description/meshes/ur5/collision/upperarm.stl" />
            </geometry>
        </collision>
        <inertial>
            <mass value="8.393" />
            <origin rpy="0 0 0" xyz="0.0 0.0 0.28" />
            <inertia ixx="0.22689067591" ixy="0.0" ixz="0.0" iyy="0.22689067591" iyz="0.0" izz="0.0151074" />
        </inertial>
    </link>
    <joint name="elbow_joint" type="revolute">
        <parent link="upper_arm_link" />
        <child link="forearm_link" />
        <origin rpy="0.0 0.0 0.0" xyz="0.0 -0.1197 0.425" />
        <axis xyz="0 1 0" />
        <limit effort="150.0" lower="-3.14159265" upper="3.14159265" velocity="3.15" />
        <dynamics damping="0.0" friction="0.0" />
    </joint>
    <link name="forearm_link">
        <visual>
            <geometry>
                <mesh filename="package://ur_description/meshes/ur5/visual/forearm.dae" />
            </geometry>
            <material name="LightGrey">
                <color rgba="0.7 0.7 0.7 1.0" />
            </material>
        </visual>
        <collision>
            <geometry>
                <mesh filename="package://ur_description/meshes/ur5/collision/forearm.stl" />
            </geometry>
        </collision>
        <inertial>
            <mass value="2.275" />
            <origin rpy="0 0 0" xyz="0.0 0.0 1" />
            <inertia ixx="0.049443313556" ixy="0.0" ixz="0.0" iyy="0.049443313556" iyz="0.0" izz="0.004095" />
        </inertial>
    </link>
    <joint name="wrist_1_joint" type="revolute">
        <parent link="forearm_link" />
        <child link="wrist_1_link" />
        <origin rpy="0.0 1.570796325 0.0" xyz="0.0 0.0 0.39225" />
        <axis xyz="0 1 0" />
        <limit effort="28.0" lower="-3.14159265" upper="3.14159265" velocity="3.2" />
        <dynamics damping="0.0" friction="0.0" />
    </joint>
    <link name="wrist_1_link">
        <visual>
            <geometry>
                <mesh filename="package://ur_description/meshes/ur5/visual/wrist1.dae" />
            </geometry>
            <material name="LightGrey">
                <color rgba="0.7 0.7 0.7 1.0" />
            </material>
        </visual>
        <collision>
            <geometry>
                <mesh filename="package://ur_description/meshes/ur5/collision/wrist1.stl" />
            </geometry>
        </collision>
        <inertial>
            <mass value="1.219" />
            <origin rpy="0 0 0" xyz="0.0 0.0 0.0" />
            <inertia ixx="0.111172755531" ixy="0.0" ixz="0.0" iyy="0.111172755531" iyz="0.0" izz="0.21942" />
        </inertial>
    </link>
    <joint name="wrist_2_joint" type="revolute">
        <parent link="wrist_1_link" />
        <child link="wrist_2_link" />
        <origin rpy="0.0 0.0 0.0" xyz="0.0 0.093 0.0" />
        <axis xyz="0 0 1" />
        <limit effort="28.0" lower="-3.14159265" upper="3.14159265" velocity="3.2" />
        <dynamics damping="0.0" friction="0.0" />
    </joint>
    <link name="wrist_2_link">
        <visual>
            <geometry>
                <mesh filename="package://ur_description/meshes/ur5/visual/wrist2.dae" />
            </geometry>
            <material name="LightGrey">
                <color rgba="0.7 0.7 0.7 1.0" />
            </material>
        </visual>
        <collision>
            <geometry>
                <mesh filename="package://ur_description/meshes/ur5/collision/wrist2.stl" />
            </geometry>
        </collision>
        <inertial>
            <mass value="1.219" />
            <origin rpy="0 0 0" xyz="0.0 0.0 0.0" />
            <inertia ixx="0.111172755531" ixy="0.0" ixz="0.0" iyy="0.111172755531" iyz="0.0" izz="0.21942" />
        </inertial>
    </link>
    <joint name="wrist_3_joint" type="revolute">
        <parent link="wrist_2_link" />
        <child link="wrist_3_link" />
        <origin rpy="0.0 0.0 0.0" xyz="0.0 0.0 0.09465" />
        <axis xyz="0 1 0" />
        <limit effort="28.0" lower="-3.14159265" upper="3.14159265" velocity="3.2" />
        <dynamics damping="0.0" friction="0.0" />
    </joint>
    <link name="wrist_3_link">
        <visual>
            <geometry>
                <mesh filename="package://ur_description/meshes/ur5/visual/wrist3.dae" />
            </geometry>
            <material name="LightGrey">
                <color rgba="0.7 0.7 0.7 1.0" />
            </material>
        </visual>
        <collision>
            <geometry>
                <mesh filename="package://ur_description/meshes/ur5/collision/wrist3.stl" />
            </geometry>
        </collision>
        <inertial>
            <mass value="0.1879" />
            <origin rpy="0 0 0" xyz="0.0 0.0 0.0" />
            <inertia ixx="0.0171364731454" ixy="0.0" ixz="0.0" iyy="0.0171364731454" iyz="0.0" izz="0.033822" />
        </inertial>
    </link>
    <joint name="ee_fixed_joint" type="fixed">
        <parent link="wrist_3_link" />
        <child link="ee_link" />
        <origin rpy="0.0 0.0 1.570796325" xyz="0.0 0.0823 0.0" />
    </joint>
    <link name="ee_link">
        <collision>
            <geometry>
                <box size="0.01 0.01 0.01" />
            </geometry>
            <origin rpy="0 0 0" xyz="-0.01 0 0" />
        </collision>
        <inertial>
            <mass value="0.1" />
            <origin xyz="0 0 0" rpy="0 0 0" />
            <inertia ixx="0.03" iyy="0.03" izz="0.03" ixy="0.0" ixz="0.0" iyz="0.0" />
        </inertial>
    </link>
    <joint name="camera_joint" type="fixed">
        <parent link="gripper_base_link" />
        <child link="camera_link" />
        <origin xyz="-0.02 0.0 0.055" rpy="0 0 0" />
    </joint>
    <link name="camera_link">
        <visual>
            <geometry>
                <box size="0.01 0.01 0.01" />
            </geometry>
            <material name="red" />
        </visual>
    </link>
    <collision>
        <origin xyz="0 0 0" rpy="0 0 0" />
        <geometry>
            <box size="0.01 0.01 0.01" />
        </geometry>
    </collision>
    <inertial>
        <mass value="1e-5" />
        <origin xyz="0 0 0" rpy="0 0 0" />
        <inertia ixx="1e-6" ixy="0" ixz="0" iyy="1e-6" iyz="0" izz="1e-6" />
    </inertial>
    <joint name="camera_optical_joint" type="fixed">
        <parent link="camera_link" />
        <child link="camera_link_optical" />
        <origin xyz="0 0 0" rpy="-1.57 0 -1.57" />
    </joint>
    <link name="camera_link_optical" />
    <gazebo reference="camera_link">
        <material>Gazebo/Red</material>
        <sensor name="camera" type="depth">
            <pose>0 0 0 0 0 0</pose>
            <visualize>false</visualize>
            <update_rate>10</update_rate>
            <camera>
                <horizontal_fov>1.089</horizontal_fov>
                <image>
                    <format>B8G8R8</format>
                    <width>640</width>
                    <height>480</height>
                </image>
                <clip>
                    <near>0.05</near>
                    <far>5.0</far>
                </clip>
            </camera>
    <plugin name="camera_controller" filename="libgazebo_ros_openni_kinect.so">
        <baseline>0.2</baseline>
        <alwaysOn>true</alwaysOn>
        <!-- Keep this zero, update_rate in the parent <sensor> tag
          will control the frame rate. -->
        <updateRate>0.0</updateRate>
        <cameraName>ur5/</cameraName>
        <imageTopicName>/ur5/depth/image_raw</imageTopicName>
        <cameraInfoTopicName>/ur5/depth/camera_info</cameraInfoTopicName>
        <depthImageTopicName>/ur5/depth/image_raw</depthImageTopicName>
        <depthImageInfoTopicName>/ur5/depth/camera_info</depthImageInfoTopicName>
        <pointCloudTopicName>/ur5/depth/points</pointCloudTopicName>
        <frameName>camera_link_optical</frameName>
        <min_depth>0.1</min_depth>
        <max_depth>50.0</max_depth>
        <pointCloudCutoff>0.05</pointCloudCutoff>
        <distortionK1>0</distortionK1>
        <distortionK2>0</distortionK2>
        <distortionK3>0</distortionK3>
        <distortionT1>0</distortionT1>
        <distortionT2>0</distortionT2>
        <CxPrime>0</CxPrime>
        <Cx>0</Cx>
        <Cy>0</Cy>
        <focalLength>0</focalLength>
        <hackBaseline>0</hackBaseline>
      </plugin>
    </sensor>
        <plugin name="gazebo_ros_control">
            <robotNamespace>/</robotNamespace>
        </plugin>
    </gazebo>
    <gazebo reference="shoulder_link">
      <selfCollide>true</selfCollide>
    </gazebo>
    <gazebo reference="upper_arm_link">
      <selfCollide>true</selfCollide>
    </gazebo>
    <gazebo reference="forearm_link">
      <selfCollide>true</selfCollide>
    </gazebo>
    <gazebo reference="wrist_1_link">
      <selfCollide>true</selfCollide>
    </gazebo>
    <gazebo reference="wrist_3_link">
      <selfCollide>true</selfCollide>
    </gazebo>
    <gazebo reference="wrist_2_link">
      <selfCollide>true</selfCollide>
    </gazebo>
    <gazebo reference="ee_link">
      <selfCollide>true</selfCollide>
    </gazebo>
    <!--  #############################################
  ########          connect model                #####
  ####################################################-->
    <!-- connect gripper to arm -->
    <joint name="gripper_robotiq_85_base_link" type="fixed">
        <parent link="ee_link" />
        <child link="gripper_base_link" />
        <origin rpy="0 0 0" xyz="0 0 0" />
    </joint>
    <!--################################################
  ########          Gripper                #####
  ####################################################-->
    <link name="gripper_base_link">
        <visual>
            <geometry>
                <mesh filename="package://robotiq_description/meshes/visual/robotiq_85_base_link.dae" />
            </geometry>
        </visual>
        <collision>
            <geometry>
                <mesh filename="package://robotiq_description/meshes/collision/robotiq_85_base_link.stl" />
            </geometry>
        </collision>
        <inertial>
            <mass value="0.636951" />
            <origin xyz="0.0 0.0 0.0" rpy="0 0 0" />
            <inertia ixx="0.000380" ixy="0.000000" ixz="0.000000" iyx="0.000000" iyy="0.001110" iyz="0.000000" izx="0.000000" izy="0.000000" izz="0.001171" />
        </inertial>
    </link>
    <joint name="gripper_finger1_joint" type="revolute">
        <parent link="gripper_base_link" />
        <child link="gripper_finger1_knuckle_link" />
        <axis xyz="0 0 1" />
        <origin rpy="3.1415 0.0 0.0" xyz="0.05490451627 0.03060114443 0.0" />
        <limit effort="1000" lower="0.0" upper="0.804" velocity="2.0" />
    </joint>
    <joint name="gripper_finger2_joint" type="revolute">
        <parent link="gripper_base_link" />
        <child link="gripper_finger2_knuckle_link" />
        <axis xyz="0 0 1" />
        <origin rpy="0.0 0.0 0.0" xyz="0.05490451627 -0.03060114443 0.0" />
        <limit effort="1000" lower="-3.14" upper="3.14" velocity="100.0" />
        <mimic joint="gripper_finger1_joint" />
    </joint>
    <link name="gripper_finger1_knuckle_link">
        <visual>
            <geometry>
                <mesh filename="package://robotiq_description/meshes/visual/robotiq_85_knuckle_link.dae" />
            </geometry>
        </visual>
        <collision>
            <geometry>
                <mesh filename="package://robotiq_description/meshes/collision/robotiq_85_knuckle_link.stl" />
            </geometry>
        </collision>
        <inertial>
            <mass value="0.018491" />
            <origin xyz="0.0 0.0 0.0" rpy="0 0 0" />
            <inertia ixx="0.000009" ixy="-0.000001" ixz="0.000000" iyx="-0.000001" iyy="0.000001" iyz="0.000000" izx="0.000000" izy="0.000000" izz="0.000010" />
        </inertial>
    </link>
 
    <link name="gripper_finger2_knuckle_link">
        <visual>
            <geometry>
                <mesh filename="package://robotiq_description/meshes/visual/robotiq_85_knuckle_link.dae" />
            </geometry>
        </visual>
        <collision>
            <geometry>
                <mesh filename="package://robotiq_description/meshes/collision/robotiq_85_knuckle_link.stl" />
            </geometry>
        </collision>
        <inertial>
            <mass value="0.018491" />
            <origin xyz="0.0 0.0 0.0" rpy="0 0 0" />
            <inertia ixx="0.000009" ixy="-0.000001" ixz="0.000000" iyx="-0.000001" iyy="0.000001" iyz="0.000000" izx="0.000000" izy="0.000000" izz="0.000010" />
        </inertial>
    </link>
 
    <joint name="gripper_finger1_finger_joint" type="fixed">
        <parent link="gripper_finger1_knuckle_link" />
        <child link="gripper_finger1_finger_link" />
        <origin rpy="0 0 0" xyz="-0.00408552455 -0.03148604435 0.0" />
    </joint>
    <joint name="gripper_finger2_finger_joint" type="fixed">
        <parent link="gripper_finger2_knuckle_link" />
        <child link="gripper_finger2_finger_link" />
        <origin rpy="0 0 0" xyz="-0.00408552455 -0.03148604435 0.0" />
    </joint>
    <link name="gripper_finger1_finger_link">
        <visual>
            <geometry>
                <mesh filename="package://robotiq_description/meshes/visual/robotiq_85_finger_link.dae" />
            </geometry>
        </visual>
        <collision>
            <geometry>
                <mesh filename="package://robotiq_description/meshes/collision/robotiq_85_finger_link.stl" />
            </geometry>
        </collision>
        <inertial>
            <mass value="0.027309" />
            <origin xyz="0.0 0.0 0.0" rpy="0 0 0" />
            <inertia ixx="0.000003" ixy="-0.000002" ixz="0.000000" iyx="-0.000002" iyy="0.000021" iyz="0.000000" izx="0.000000" izy="0.000000" izz="0.000020" />
        </inertial>
    </link>
    
   
    <link name="gripper_finger2_finger_link">
        <visual>
            <geometry>
                <mesh filename="package://robotiq_description/meshes/visual/robotiq_85_finger_link.dae" />
            </geometry>
        </visual>
        <collision>
            <geometry>
                <mesh filename="package://robotiq_description/meshes/collision/robotiq_85_finger_link.stl" />
            </geometry>
        </collision>
        <inertial>
            <mass value="0.027309" />
            <origin xyz="0.0 0.0 0.0" rpy="0 0 0" />
            <inertia ixx="0.000003" ixy="-0.000002" ixz="0.000000" iyx="-0.000002" iyy="0.000021" iyz="0.000000" izx="0.000000" izy="0.000000" izz="0.000020" />
        </inertial>
    </link>
   
    <joint name="gripper_finger1_inner_knuckle_joint" type="continuous">
        <parent link="gripper_base_link" />
        <child link="gripper_finger1_inner_knuckle_link" />
        <axis xyz="0 0 1" />
        <origin rpy="3.1415 0.0 0.0" xyz="0.06142 0.0127 0" />
        <limit effort="0.1" lower="-3.14" upper="3.14" velocity="100.0" />
        <mimic joint="gripper_finger1_joint" offset="0" />
    </joint>
    <joint name="gripper_finger2_inner_knuckle_joint" type="continuous">
        <parent link="gripper_base_link" />
        <child link="gripper_finger2_inner_knuckle_link" />
        <axis xyz="0 0 1" />
        <origin rpy="0 0 0" xyz="0.06142 -0.0127 0" />
        <limit effort="0.1" lower="-3.14" upper="3.14" velocity="100.0" />
        <mimic joint="gripper_finger1_joint" offset="0" />
    </joint>
    <link name="gripper_finger1_inner_knuckle_link">
        <visual>
            <geometry>
                <mesh filename="package://robotiq_description/meshes/visual/robotiq_85_inner_knuckle_link.dae" />
            </geometry>
        </visual>
        <collision>
            <geometry>
                <mesh filename="package://robotiq_description/meshes/collision/robotiq_85_inner_knuckle_link.stl" />
            </geometry>
        </collision>
        <inertial>
            <mass value="0.029951" />
            <origin xyz="0.0 0.0 0.0" rpy="0 0 0" />
            <inertia ixx="0.000039" ixy="0.000000" ixz="0.000000" iyx="0.000000" iyy="0.000005" iyz="0.000000" izx="0.000000" izy="0.000000" izz="0.000035" />
        </inertial>
    </link>
    <link name="gripper_finger2_inner_knuckle_link">
        <visual>
            <geometry>
                <mesh filename="package://robotiq_description/meshes/visual/robotiq_85_inner_knuckle_link.dae" />
            </geometry>
        </visual>
        <collision>
            <geometry>
                <mesh filename="package://robotiq_description/meshes/collision/robotiq_85_inner_knuckle_link.stl" />
            </geometry>
        </collision>
        <inertial>
            <mass value="0.029951" />
            <origin xyz="0.0 0.0 0.0" rpy="0 0 0" />
            <inertia ixx="0.000039" ixy="0.000000" ixz="0.000000" iyx="0.000000" iyy="0.000005" iyz="0.000000" izx="0.000000" izy="0.000000" izz="0.000035" />
        </inertial>
    </link>
    <joint name="gripper_finger1_finger_tip_joint" type="continuous">
        <parent link="gripper_finger1_inner_knuckle_link" />
        <child link="gripper_finger1_finger_tip_link" />
        <axis xyz="0 0 1" />
        <origin rpy="0.0 0.0 0.0" xyz="0.04303959807 -0.03759940821 0.0" />
        <limit effort="0.1" lower="-3.14" upper="3.14" velocity="100.0" />
        <mimic joint="gripper_finger1_joint" multiplier="-1" />
    </joint>
    <joint name="gripper_finger2_finger_tip_joint" type="continuous">
        <parent link="gripper_finger2_inner_knuckle_link" />
        <child link="gripper_finger2_finger_tip_link" />
        <axis xyz="0 0 1" />
        <origin rpy="0.0 0.0 0.0" xyz="0.04303959807 -0.03759940821  0.0" />
        <limit effort="0.1" lower="-3.14" upper="3.14" velocity="100.0" />
        <mimic joint="gripper_finger1_joint" multiplier="-1" />
    </joint>
    <link name="gripper_finger1_finger_tip_link">
        <visual>
            <geometry>
                <mesh filename="package://robotiq_description/meshes/visual/robotiq_85_finger_tip_link.dae" />
            </geometry>
        </visual>
        <collision>
            <geometry>
                <mesh filename="package://robotiq_description/meshes/collision/robotiq_85_finger_tip_link.stl" />
            </geometry>
        </collision>
        <inertial>
            <mass value="0.019555" />
            <origin xyz="0.0 0.0 0.0" rpy="0 0 0" />
            <inertia ixx="0.000002" ixy="0.000000" ixz="0.000000" iyx="0.000000" iyy="0.000005" iyz="0.000000" izx="0.000000" izy="0.000000" izz="0.000006" />
        </inertial>
    </link>
   <gazebo reference="gripper_finger1_finger_tip_link">
      <kp>1000000.0</kp>
      <kd>1.0</kd>
      <mu1>1.0</mu1>
      <mu2>1.0</mu2>
      <minDepth>0.001</minDepth>
    </gazebo>
    <link name="gripper_finger2_finger_tip_link">
        <visual>
            <geometry>
                <mesh filename="package://robotiq_description/meshes/visual/robotiq_85_finger_tip_link.dae" />
            </geometry>
        </visual>
        <collision>
            <geometry>
                <mesh filename="package://robotiq_description/meshes/collision/robotiq_85_finger_tip_link.stl" />
            </geometry>
        </collision>
        <inertial>
            <mass value="0.019555" />
            <origin xyz="0.0 0.0 0.0" rpy="0 0 0" />
            <inertia ixx="0.000002" ixy="0.000000" ixz="0.000000" iyx="0.000000" iyy="0.000005" iyz="0.000000" izx="0.000000" izy="0.000000" izz="0.000006" />
        </inertial>
    </link>
    <gazebo reference="gripper_finger2_finger_tip_link">
      <kp>1000000.0</kp>
      <kd>1.0</kd>
      <mu1>1.5</mu1>
      <mu2>1.5</mu2>
      <minDepth>0.000</minDepth>
    </gazebo>
    <transmission name="gripper_finger1_trans">
        <type>transmission_interface/SimpleTransmission</type>
        <joint name="gripper_finger1_joint">
            <hardwareInterface>hardware_interface/EffortJointInterface</hardwareInterface>
        </joint>
        <actuator name="gripper_finger1_motor">
            <mechanicalReduction>1</mechanicalReduction>
            <hardwareInterface>hardware_interface/EffortJointInterface</hardwareInterface>
        </actuator>
    </transmission>
    <gazebo>
        <!-- loading plugin: mimic joints works in gazebo now -->
        <plugin name="gazebo_mimic_joint_plugin_1" filename="libroboticsgroup_gazebo_mimic_joint_plugin.so">
                    <joint>gripper_finger1_joint</joint>
                    <mimicJoint>gripper_finger2_joint</mimicJoint>
                    
                    
                    
 </plugin>
        <plugin name="gazebo_mimic_joint_plugin_2" filename="libroboticsgroup_gazebo_mimic_joint_plugin.so">
                    <joint>gripper_finger1_joint</joint>
                    <mimicJoint>gripper_finger2_inner_knuckle_joint</mimicJoint>
                   
                    
 </plugin>
       <plugin name="gazebo_mimic_joint_plugin_3" filename="libroboticsgroup_gazebo_mimic_joint_plugin.so">
                    <joint>gripper_finger1_joint</joint>
                    <mimicJoint>gripper_finger1_inner_knuckle_joint</mimicJoint>
             
                  
 </plugin>
       <plugin name="gazebo_mimic_joint_plugin_4" filename="libroboticsgroup_gazebo_mimic_joint_plugin.so">
                    <joint>gripper_finger1_joint</joint>
                    <mimicJoint>gripper_finger1_finger_tip_joint</mimicJoint>
                    <multiplier>-1.0</multiplier>
                    <offset>0.0</offset>
                    <sensitiveness>0.0</sensitiveness>
                 
 </plugin>
       <plugin name="gazebo_mimic_joint_plugin_5" filename="libroboticsgroup_gazebo_mimic_joint_plugin.so">
                    <joint>gripper_finger1_joint</joint>
                    <mimicJoint>gripper_finger2_finger_tip_joint</mimicJoint>
                    <multiplier>-1.0</multiplier>
                 
        </plugin>
    </gazebo>
    <!--using the grasp plugin so that the gripper can grasp things in simulation-->
    <gazebo>
        <plugin name="gazebo_grasp_fix" filename="libgazebo_grasp_fix.so">
            <arm>
                <arm_name>ur5</arm_name>
                <palm_link>wrist_3_link</palm_link>
                <gripper_link>gripper_finger1_finger_tip_link</gripper_link>
                <gripper_link>gripper_finger2_finger_tip_link</gripper_link>
            </arm>
            <forces_angle_tolerance>100</forces_angle_tolerance>
            <update_rate>40</update_rate>
            <grip_count_threshold>1</grip_count_threshold>
            <max_grip_count>2</max_grip_count>
            <release_tolerance>0.0100</release_tolerance>
            <disable_collisions_on_attach>false</disable_collisions_on_attach>
            <contact_topic>__default_topic__</contact_topic>
        </plugin>
    </gazebo>
    <transmission name="tran1">
        <type>transmission_interface/SimpleTransmission</type>
        <joint name="shoulder_pan_joint">
            <hardwareInterface>hardware_interface/EffortJointInterface</hardwareInterface>
        </joint>
        <actuator name="motor1">
            <hardwareInterface>hardware_interface/EffortJointInterface</hardwareInterface>
            <mechanicalReduction>1</mechanicalReduction>
        </actuator>
    </transmission>
    <transmission name="tran2">
        <type>transmission_interface/SimpleTransmission</type>
        <joint name="shoulder_lift_joint">
            <hardwareInterface>hardware_interface/EffortJointInterface</hardwareInterface>
        </joint>
        <actuator name="motor2">
            <hardwareInterface>hardware_interface/EffortJointInterface</hardwareInterface>
            <mechanicalReduction>1</mechanicalReduction>
        </actuator>
    </transmission>
    <transmission name="tran3">
        <type>transmission_interface/SimpleTransmission</type>
        <joint name="elbow_joint">
            <hardwareInterface>hardware_interface/EffortJointInterface</hardwareInterface>
        </joint>
        <actuator name="motor3">
            <hardwareInterface>hardware_interface/EffortJointInterface</hardwareInterface>
            <mechanicalReduction>1</mechanicalReduction>
        </actuator>
    </transmission>
    <transmission name="tran4">
        <type>transmission_interface/SimpleTransmission</type>
        <joint name="wrist_1_joint">
            <hardwareInterface>hardware_interface/EffortJointInterface</hardwareInterface>
        </joint>
        <actuator name="motor4">
            <hardwareInterface>hardware_interface/EffortJointInterface</hardwareInterface>
            <mechanicalReduction>1</mechanicalReduction>
        </actuator>
    </transmission>
    <transmission name="tran5">
        <type>transmission_interface/SimpleTransmission</type>
        <joint name="wrist_2_joint">
            <hardwareInterface>hardware_interface/EffortJointInterface</hardwareInterface>
        </joint>
        <actuator name="motor5">
            <hardwareInterface>hardware_interface/EffortJointInterface</hardwareInterface>
            <mechanicalReduction>1</mechanicalReduction>
        </actuator>
    </transmission>
    <transmission name="tran6">
        <type>transmission_interface/SimpleTransmission</type>
        <joint name="wrist_3_joint">
            <hardwareInterface>hardware_interface/EffortJointInterface</hardwareInterface>
        </joint>
        <actuator name="motor6">
            <hardwareInterface>hardware_interface/EffortJointInterface</hardwareInterface>
            <mechanicalReduction>1</mechanicalReduction>
        </actuator>
    </transmission>
    <!-- define the ur5's position and orientation in the world coordinate system -->
    <link name="world" />
    <joint name="world_joint" type="fixed">
        <parent link="world" />
        <child link="base_link" />
        <!-- TODO: check base_link name of robot -->
        <origin rpy="0.0 0.0 0.0" xyz="0.0 0.0 0.0" />
    </joint>
    <gazebo>
        <plugin name="gazebo_ros_control" filename="libgazebo_ros_control.so">
            <robotNamespace>/</robotNamespace>
        </plugin>
    </gazebo>
    <transmission name="trans_gripper_finger1_joint">
        <type>transmission_interface/SimpleTransmission</type>
        <joint name="gripper_finger1_joint">
            <hardwareInterface>hardware_interface/EffortJointInterface</hardwareInterface>
        </joint>
        <actuator name="gripper_finger1_joint_motor">
            <hardwareInterface>hardware_interface/EffortJointInterface</hardwareInterface>
            <mechanicalReduction>1</mechanicalReduction>
        </actuator>
    </transmission>
    <transmission name="trans_gripper_finger2_joint">
        <type>transmission_interface/SimpleTransmission</type>
        <joint name="gripper_finger2_joint">
            <hardwareInterface>hardware_interface/EffortJointInterface</hardwareInterface>
        </joint>
        <actuator name="gripper_finger2_joint_motor">
            <hardwareInterface>hardware_interface/EffortJointInterface</hardwareInterface>
            <mechanicalReduction>1</mechanicalReduction>
        </actuator>
    </transmission>
    <transmission name="trans_gripper_finger1_inner_knuckle_joint">
        <type>transmission_interface/SimpleTransmission</type>
        <joint name="gripper_finger1_inner_knuckle_joint">
            <hardwareInterface>hardware_interface/EffortJointInterface</hardwareInterface>
        </joint>
        <actuator name="gripper_finger1_inner_knuckle_joint_motor">
            <hardwareInterface>hardware_interface/EffortJointInterface</hardwareInterface>
            <mechanicalReduction>1</mechanicalReduction>
        </actuator>
    </transmission>
    <transmission name="trans_gripper_finger2_inner_knuckle_joint">
        <type>transmission_interface/SimpleTransmission</type>
        <joint name="gripper_finger2_inner_knuckle_joint">
            <hardwareInterface>hardware_interface/EffortJointInterface</hardwareInterface>
        </joint>
        <actuator name="gripper_finger2_inner_knuckle_joint_motor">
            <hardwareInterface>hardware_interface/EffortJointInterface</hardwareInterface>
            <mechanicalReduction>1</mechanicalReduction>
        </actuator>
    </transmission>
    <transmission name="trans_gripper_finger1_finger_tip_joint">
        <type>transmission_interface/SimpleTransmission</type>
        <joint name="gripper_finger1_finger_tip_joint">
            <hardwareInterface>hardware_interface/EffortJointInterface</hardwareInterface>
        </joint>
        <actuator name="gripper_finger1_finger_tip_joint_motor">
            <hardwareInterface>hardware_interface/EffortJointInterface</hardwareInterface>
            <mechanicalReduction>1</mechanicalReduction>
        </actuator>
    </transmission>
    <transmission name="trans_gripper_finger2_finger_tip_joint">
        <type>transmission_interface/SimpleTransmission</type>
        <joint name="gripper_finger2_finger_tip_joint">
            <hardwareInterface>hardware_interface/EffortJointInterface</hardwareInterface>
        </joint>
        <actuator name="gripper_finger2_finger_tip_joint_motor">
            <hardwareInterface>hardware_interface/EffortJointInterface</hardwareInterface>
            <mechanicalReduction>1</mechanicalReduction>
        </actuator>
    </transmission>
      <link name="camera_link_1">
    <collision>
      <origin xyz="0 0 0" rpy="0 0 0"/>
      <geometry>
    <box size="0.1 0.1 0.05"/>
      </geometry>
    </collision>

    <visual>
      <origin xyz="0 0 0" rpy="0 0 0"/>
      <geometry>
    <box size="0.1 0.1 0.05"/>
      </geometry>
      <material name="red"/>
    </visual>

    <inertial>
      <mass value="1e-5" />
      <origin xyz="0 0 0" rpy="0 0 0"/>
      <inertia ixx="1e-6" ixy="0" ixz="0" iyy="1e-6" iyz="0" izz="1e-6" />
    </inertial>
  </link>
  <gazebo reference="camera_link_1">
        <material>Gazebo/Red</material>
        <sensor name="camera" type="depth">
            <pose>0 0 0 0 0 0 </pose>
            <visualize>true</visualize>
            <update_rate>30</update_rate>
            <camera>
                <horizontal_fov>1.089</horizontal_fov>
                <image>
                    <format>B8G8R8</format>
                    <width>640</width>
                    <height>480</height>
                </image>
                <clip>
                    <near>0.05</near>
                    <far>5.0</far>
                </clip>
                 <noise>
                   <type>gaussian</type>
          <!-- Noise is sampled independently per pixel on each frame.
               That pixel's noise value is added to each of its color
               channels, which at that point lie in the range [0,1]. -->
                   <mean>0.0</mean>
                   <stddev>0.035</stddev>
                </noise>
              </camera>
    <plugin name="camera_controller" filename="libgazebo_ros_openni_kinect.so">
        <baseline>0.2</baseline>
        <alwaysOn>true</alwaysOn>
        <!-- Keep this zero, update_rate in the parent <sensor> tag
          will control the frame rate. -->
        <updateRate>0.0</updateRate>
        <cameraName>ur5_1/</cameraName>
        <imageTopicName>/ur5/depth/image_raw_1</imageTopicName>
        <cameraInfoTopicName>/ur5/depth/camera_info_1</cameraInfoTopicName>
        <depthImageTopicName>/ur5/depth/image_raw_1</depthImageTopicName>
        <depthImageInfoTopicName>/ur5/depth/camera_info_1</depthImageInfoTopicName>
        <pointCloudTopicName>/ur5/depth/points_1</pointCloudTopicName>
        <frameName>camera_link_1</frameName>
        <min_depth>0.1</min_depth>
        <max_depth>50.0</max_depth>
        <pointCloudCutoff>0.05</pointCloudCutoff>
        <distortionK1>0</distortionK1>
        <distortionK2>0</distortionK2>
        <distortionK3>0</distortionK3>
        <distortionT1>0</distortionT1>
        <distortionT2>0</distortionT2>
        <CxPrime>0</CxPrime>
        <Cx>0</Cx>
        <Cy>0</Cy>
        <focalLength>0</focalLength>
        <hackBaseline>0</hackBaseline>
      </plugin>
    </sensor>
  </gazebo>
    <joint name="camera_world_joint" type="fixed">
    <parent link="world" />
    <child link = "camera_link_1" />
    <origin xyz="0.9 -0.079916 2.00" rpy="0.0 1.20 3.14" />
  </joint>
    
    
</robot>

